<?xml version="1.0" ?>
<!-- =================================================================================== -->
<!-- |    This document was autogenerated by xacro from updated_example.urdf.xacro     | -->
<!-- |    EDITING THIS FILE BY HAND IS NOT RECOMMENDED                                 | -->
<!-- =================================================================================== -->
<robot name="ptu_d46">
  <link name="base_link"/>
  <link name="ptu_tilt_link">
    <inertial>
      <mass value="0.65"/>
      <origin rpy="0 0 0" xyz="0 0 0"/>
      <inertia ixx="0.0001" ixy="0" ixz="0" iyy="0.0001" iyz="0" izz="0.0001"/>
    </inertial>
    <visual>
      <material name="ptu_body_color">
        <color rgba="0.3 0.3 0.3 1.0"/>
      </material>
      <geometry>
        <mesh filename="package://flir_ptu_description/meshes/flir-ptu-tilt-motor.stl"/>
      </geometry>
    </visual>
    <collision>
      <geometry>
        <mesh filename="package://flir_ptu_description/meshes/flir-ptu-tilt-motor-collision.stl"/>
      </geometry>
    </collision>
  </link>
  <gazebo reference="ptu_tilt_link">
    <material>Gazebo/DarkGrey</material>
  </gazebo>
  <link name="ptu_pan_link">
    <inertial>
      <mass value="0.65"/>
      <origin rpy="0 0 0" xyz="0 0 0"/>
      <inertia ixx="0.0001" ixy="0" ixz="0" iyy="0.0001" iyz="0" izz="0.0001"/>
    </inertial>
    <visual>
      <material name="ptu_body_color">
        <color rgba="0.3 0.3 0.3 1.0"/>
      </material>
      <geometry>
        <mesh filename="package://flir_ptu_description/meshes/flir-ptu-pan-motor.stl"/>
      </geometry>
    </visual>
    <collision>
      <geometry>
        <mesh filename="package://flir_ptu_description/meshes/flir-ptu-pan-motor-collision.stl"/>
      </geometry>
    </collision>
  </link>
  <gazebo reference="ptu_pan_link">
    <material>Gazebo/DarkGrey</material>
  </gazebo>
  <link name="ptu_base_link">
    <inertial>
      <mass value="2e-06"/>
      <inertia ixx="1.1e-09" ixy="0" ixz="0" iyy="1.1e-09" iyz="0" izz="1.1e-09"/>
    </inertial>
  </link>
  <link name="ptu_tilted_link">
    <visual>
      <material name="ptu_body_color">
        <color rgba="0.3 0.3 0.3 1.0"/>
      </material>
      <geometry>
        <mesh filename="package://flir_ptu_description/meshes/flir-ptu-camera-mount.stl"/>
      </geometry>
    </visual>
    <collision>
      <geometry>
        <mesh filename="package://flir_ptu_description/meshes/flir-ptu-camera-mount.stl"/>
      </geometry>
    </collision>
  </link>
  <link name="ptu_mount_link">
    <inertial>
      <mass value="2e-06"/>
      <inertia ixx="1.1e-09" ixy="0" ixz="0" iyy="1.1e-09" iyz="0" izz="1.1e-09"/>
    </inertial>
  </link>
  <joint name="ptu_base" type="fixed">
    <parent link="ptu_base_link"/>
    <child link="ptu_pan_link"/>
    <origin xyz="0 0 0"/>
  </joint>
  <!-- The pan joint -->
  <joint name="ptu_pan" type="revolute">
    <parent link="ptu_pan_link"/>
    <origin rpy="-1.5708 0 0.0" xyz="0 -0.00955 0.046774"/>
    <child link="ptu_tilt_link"/>
    <axis rpy="3.14159 0 0" xyz="0 -1 0"/>
    <limit effort="30" lower="-2.775" upper="2.775" velocity="1.0"/>
  </joint>
  <transmission name="ptu_pan_trans">
    <type>transmission_interface/SimpleTransmission</type>
    <joint name="ptu_pan">
      <hardwareInterface>PositionJointInterface</hardwareInterface>
    </joint>
    <actuator name="ptu_pan_motor">
      <mechanicalReduction>1</mechanicalReduction>
    </actuator>
  </transmission>
  <!-- The tilt joint -->
  <joint name="ptu_tilt" type="revolute">
    <parent link="ptu_tilt_link"/>
    <origin rpy="-1.5708 0 0" xyz="0 -0.043713 0"/>
    <child link="ptu_tilted_link"/>
    <axis xyz="0 1 0"/>
    <limit effort="30" lower="-0.82" upper="0.52" velocity="1.0"/>
  </joint>
  <transmission name="ptu_tilt_trans">
    <type>transmission_interface/SimpleTransmission</type>
    <joint name="ptu_tilt">
      <hardwareInterface>PositionJointInterface</hardwareInterface>
    </joint>
    <actuator name="ptu_tilt_motor">
      <mechanicalReduction>1</mechanicalReduction>
    </actuator>
  </transmission>
  <!-- Fixed joint to provide a convenient attachment point for accessories. -->
  <joint name="ptu_mount" type="fixed">
    <parent link="ptu_tilted_link"/>
    <child link="ptu_mount_link"/>
    <origin rpy="3.1416 0 0" xyz="0 0 -0.039116"/>
  </joint>
  <!-- Create a fixed joint to connect the PTU to the rest of the robot -->
  <joint name="base_to_ptu_base" type="fixed">
    <parent link="base_link"/>
    <child link="ptu_base_link"/>
    <origin xyz="0 0 0"/>
  </joint>
  <!-- If you had a lidar or some other device mounted on the PTU, you would create another
       fixed joint here between the ptu_mount link and the origin of the device. -->
  <material name="zed_mat">
    <color rgba="0.8 0.8 0.8 0.8"/>
  </material>
  <material name="zedm_mat">
    <color rgba="0 0 0 0.9"/>
  </material>
  <material name="zed2_mat">
    <color rgba="0.25 0.25 0.25 0.99"/>
  </material>
  <material name="zed2i_mat">
    <color rgba="0.25 0.25 0.25 0.99"/>
  </material>
  <!-- Camera mounting point (the threaded screw hole in the bottom) -->
  <link name="zed_base_link"/>
  <joint name="zed_base_joint" type="fixed">
    <parent link="base_link"/>
    <child link="zed_base_link"/>
    <origin rpy="0.0 0.0 0.0" xyz="0.0 0.0 0.0"/>
  </joint>
  <!-- Camera Center -->
  <link name="zed_camera_center">
    <visual>
      <origin rpy="0 0 0" xyz="0.0 0 0"/>
      <geometry>
        <mesh filename="package://zed_interfaces/meshes/zed.stl"/>
      </geometry>
      <material name="zed_mat"/>
    </visual>
    <collision>
      <geometry>
        <mesh filename="package://zed_interfaces/meshes/zed.stl"/>
      </geometry>
    </collision>
  </link>
  <joint name="zed_camera_center_joint" type="fixed">
    <parent link="zed_base_link"/>
    <child link="zed_camera_center"/>
    <origin rpy="0 0.05 0" xyz="0 0 0.015"/>
  </joint>
  <!-- Left Camera -->
  <link name="zed_left_camera_frame"/>
  <joint name="zed_left_camera_joint" type="fixed">
    <parent link="zed_camera_center"/>
    <child link="zed_left_camera_frame"/>
    <origin rpy="0 0 0" xyz="0 0.06 0"/>
  </joint>
  <link name="zed_left_camera_optical_frame"/>
  <joint name="zed_left_camera_optical_joint" type="fixed">
    <origin rpy="-1.5707963267948966 0.0 -1.5707963267948966" xyz="-0.01 0 0"/>
    <parent link="zed_left_camera_frame"/>
    <child link="zed_left_camera_optical_frame"/>
  </joint>
  <!-- Right Camera -->
  <link name="zed_right_camera_frame"/>
  <joint name="zed_right_camera_joint" type="fixed">
    <parent link="zed_camera_center"/>
    <child link="zed_right_camera_frame"/>
    <origin rpy="0 0 0" xyz="0 -0.06 0"/>
  </joint>
  <link name="zed_right_camera_optical_frame"/>
  <joint name="zed_right_camera_optical_joint" type="fixed">
    <origin rpy="-1.5707963267948966 0.0 -1.5707963267948966" xyz="-0.01 0 0"/>
    <parent link="zed_right_camera_frame"/>
    <child link="zed_right_camera_optical_frame"/>
  </joint>
  <link name="base_link"/>
  <joint name="zed2i_camera_joint" type="fixed">
    <origin rpy="0 0 0" xyz="0 0 0"/>
    <!-- Adjust position and orientation as needed -->
    <parent link="ptu_mount_link"/>
    <child link="zed2i_left_camera_frame"/>
  </joint>
  <!-- Camera mounting point (the threaded screw hole in the bottom) -->
  <link name="zed2i_base_link"/>
  <joint name="zed2i_base_joint" type="fixed">
    <parent link="ptu_mount_link"/>
    <child link="zed2i_base_link"/>
    <origin rpy="0 0 0" xyz="0 0 0"/>
  </joint>
  <!-- Camera Center -->
  <link name="zed2i_camera_center">
    <visual>
      <origin rpy="0 0 0" xyz="0.0 0 0"/>
      <geometry>
        <mesh filename="package://zed_interfaces/meshes/zed2.stl"/>
      </geometry>
      <material name="zed2_mat"/>
    </visual>
    <collision>
      <geometry>
        <mesh filename="package://zed_interfaces/meshes/zed2.stl"/>
      </geometry>
    </collision>
  </link>
  <joint name="zed2i_camera_center_joint" type="fixed">
    <parent link="zed2i_base_link"/>
    <child link="zed2i_camera_center"/>
    <origin rpy="0 0.05 0" xyz="0 0 0.015"/>
  </joint>
  <!-- Left Camera -->
  <link name="zed2i_left_camera_frame"/>
  <joint name="zed2i_left_camera_joint" type="fixed">
    <parent link="zed2i_camera_center"/>
    <child link="zed2i_left_camera_frame"/>
    <origin rpy="0 0 0" xyz="0 0.06 0"/>
  </joint>
  <link name="zed2i_left_camera_optical_frame"/>
  <joint name="zed2i_left_camera_optical_joint" type="fixed">
    <origin rpy="-1.5707963267948966 0.0 -1.5707963267948966" xyz="-0.01 0 0"/>
    <parent link="zed2i_left_camera_frame"/>
    <child link="zed2i_left_camera_optical_frame"/>
  </joint>
  <!-- Right Camera -->
  <link name="zed2i_right_camera_frame"/>
  <joint name="zed2i_right_camera_joint" type="fixed">
    <parent link="zed2i_camera_center"/>
    <child link="zed2i_right_camera_frame"/>
    <origin rpy="0 0 0" xyz="0 -0.06 0"/>
  </joint>
  <link name="zed2i_right_camera_optical_frame"/>
  <joint name="zed2i_right_camera_optical_joint" type="fixed">
    <origin rpy="-1.5707963267948966 0.0 -1.5707963267948966" xyz="-0.01 0 0"/>
    <parent link="zed2i_right_camera_frame"/>
    <child link="zed2i_right_camera_optical_frame"/>
  </joint>
  <link name="zed2i_mag_link"/>
  <joint name="zed2i_mag_joint" type="fixed">
    <parent link="zed2i_camera_center"/>
    <child link="zed2i_mag_link"/>
    <origin rpy="0 0 0" xyz="0 0 0"/>
  </joint>
  <link name="zed2i_baro_link"/>
  <joint name="zed2i_baro_joint" type="fixed">
    <parent link="zed2i_camera_center"/>
    <child link="zed2i_baro_link"/>
    <origin rpy="0 0 0" xyz="0 0 0"/>
  </joint>
  <link name="zed2i_temp_left_link"/>
  <joint name="zed2i_temp_left_joint" type="fixed">
    <parent link="zed2i_left_camera_frame"/>
    <child link="zed2i_temp_left_link"/>
    <origin rpy="0 0 0" xyz="0 0 0"/>
  </joint>
  <link name="zed2i_temp_right_link"/>
  <joint name="zed2i_temp_right_joint" type="fixed">
    <parent link="zed2i_right_camera_frame"/>
    <child link="zed2i_temp_right_link"/>
    <origin rpy="0 0 0" xyz="0 0 0"/>
  </joint>
</robot>

